Workbook

Sheet Personal
A1: DNI | B1: Código | C1: Nombre | D1: Foto | E1: Fecha de Ingreso | F1: Puesto Real | G1: CC Real | H1: Unidad Real | I1: Nombre Host | J1: Nueva Tajeta Micros
A2: 08869374 | B2: 0000F00015 | C2: PINEDA LOPEZ GLADYS DIANA | D2: SI | E2: 35080 | F2: Contralora Regional | G2: Contraloría | H2: Contraloría | I2: LIMCNTCG
A3: 10287285 | B3: 0000000025 | C3: TOULLIER ARTEAGA MIGUEL ANGEL | D3: SI | E3: 35255 | F3: Jefe de Gimnasio | G3: Gym & Spa | H3: División de Habitaciones (Operaciones) | I3: LIMDHGYM
A4: 10479259 | B4: 0000000031 | C4: MEDINA CASTILLO ALVARO GERARDO | D4: SI | E4: 35262 | F4: Sub Gerente de A&B | G4: Gerencia A&B | H4: Alimentos y Bebidas | I4: LIMAYBSGER
A5: 08738298 | B5: 0000F00011 | C5: CASTRO MORA NELLY YOLANDA | D5: SI | E5: 35277 | F5: Gerente de Compras Regional | G5: Compras | H5: Compras | I5: LIMCOMPGCR
A6: 09649733 | B6: 0000000037 | C6: OBARA AVI JUAN FERNANDO | D6: SI | E6: 35278 | F6: Gerente de Compras | G6: Compras | H6: Compras | I6: LIMCOMPGC | Y6: 8va Gen.
A7: 06111494 | B7: 0000000086 | C7: MOTA CASTRO JIM EDUARDO | D7: SI | E7: 35310 | F7: Auditor de Ingresos | G7: Auditoría de Ingresos | H7: Contraloría | I7: LIMCNTAI
A8: 09933993 | B8: 0000000116 | C8: SARMIENTO CONTRERAS RICARDO MARTIN | D8: SI | E8: 35317 | F8: Empleado de Lavanderia | G8: Lavandería | H8: División de Habitaciones (Operaciones) | I8: LIMDH
A9: 22090547 | B9: 0000000232 | C9: SALAS MENDOZA ROMULO OMAR | D9: SI | E9: 35327 | F9: Técnico Electricista | G9: Mantenimiento | H9: Mantenimiento | I9: LIMMANT
A10: 44673548 | B10: 0000001529 | C10: VILCHEZ QUISPE SHEILLA FIORELLA | D10: SI | E10: 44991 | F10: Team Leader de Banquetes | G10: Banquetes | H10: Alimentos y Bebidas | I10: LIMAYBBQ
A11: 09692690 | B11: 0000000269 | C11: VEGA ARRATEA JAVIER VICTOR | D11: SI | E11: 35338 | F11: Supervisor Jr. de Steward | G11: Steward | H11: Alimentos y Bebidas
A12: 08876264 | B12: 0000000260 | C12: SALAS PARRA MONICA | D12: SI | E12: 35339 | F12: Costurero | G12: Housekeeping | H12: División de Habitaciones (Operaciones) | I12: LIMDH
A13: 03822662 | B13: 0000000282 | C13: ACHA ZAPATA JOAQUIN ALEJANDRO | D13: SI | E13: 35345 | F13: Supervisor Senior de Control y Monitoreo | G13: Control y Monitoreo | H13: Control y Monitoreo | I13: LIMCMSCM
A14: 08906688 | B14: 0000000304 | C14: LLANCA ZUÑIGA JIMMY WIELER | D14: SI | E14: 35354 | F14: Técnico de Mantenimiento | G14: Mantenimiento | H14: Mantenimiento | I14: LIMMANT
A15: 09789487 | B15: 0000000323 | C15: HERNANDEZ HERNANDEZ EDILBRANDO | D15: SI | E15: 35370 | F15: Supervisor de Control y Monitoreo | G15: Control y Monitoreo | H15: Control y Monitoreo | I15: LIMCMSCM
A16: 09884050 | B16: 0000000345 | C16: MARTINEZ SOTELO LUIS ENRIQUE | D16: SI | E16: 35401 | F16: Supervisor Senior de Limpieza | G16: Limpieza | H16: División de Habitaciones (Operaciones) | I16: LIMDH
A17: 10793198 | B17: 0000001374 | C17: VIDAL LORENZZI FRANCO | D17: SI | E17: 43640 | F17: Recepcionista | G17: Recepción | H17: División de Habitaciones (Operaciones) | I17: LIMDHREC
A18: 10096345 | B18: 0000000445 | C18: CANO VEGA ALFREDO FRAY | D18: SI | E18: 35583 | F18: Supervisor Jr. De Limpieza | G18: Limpieza | H18: División de Habitaciones (Operaciones) | I18: LIMDH
A19: 08971022 | B19: 0000000508 | C19: VIGO MONTORO LUCIA | D19: SI | E19: 35846 | F19: Empleado de Housekeeping | G19: Housekeeping | H19: División de Habitaciones (Operaciones) | I19: LIMDH
A20: 72787160 | B20: 0000001628 | C20: VERGARA MORENO YADELIN ANAHI | D20: SI | E20: 45482 | F20: Ayudante de Cocina | G20: Cocina La Locanda | H20: Cocina
A21: 10806822 | B21: 0000000423 | C21: UGAZ OLIVARES PALOMA | D21: SI | E21: 37539 | F21: Supervisor Senior de A&B | G21: Lobby | H21: Alimentos y Bebidas
A22: 09398469 | B22: 0000000732 | C22: TELLO FARFAN JAVIER ALEJANDRO | D22: SI | E22: 37956 | F22: Empleado Puesto de Control | G22: Control y Monitoreo | H22: Control y Monitoreo | I22: LIMCMEPC
A23: 41108703 | B23: 0000000735 | C23: VELIZ CHUCO WILIAN | D23: SI | E23: 38054 | F23: Jardinero | G23: Mantenimiento | H23: Mantenimiento | I23: LIMMANT
A24: 25830800 | B24: 0000000736 | C24: PACHAS DELGADO CARMEN ROSA | D24: SI | E24: 38078 | F24: Ejecutiva de Ventas | G24: Ventas | H24: Ventas y Marketing | I24: LIMVMVEN
A25: 40856376 | B25: 0000000772 | C25: CARHUANCOTA CHAVEZ ANDRES ALBERTO | D25: SI | E25: 38596 | F25: Asistente Senior de Contabilidad | G25: Contabilidad | H25: Contraloría | I25: LIMCNTCONT3
A26: 08694596 | B26: 0000000783 | C26: QUISPE LOPEZ RICARDO | D26: SI | E26: 38749 | F26: Limpieza de Cocina | G26: Steward | H26: Alimentos y Bebidas
A27: 40235456 | B27: 0000000806 | C27: TRUJILLO GARAY MONICA ALEJANDRA | D27: SI | E27: 38899 | F27: Gerente de Congresos y Convenciones | G27: Ventas | H27: Ventas y Marketing | I27: LIMVMVEN
A28: 07448369 | B28: 0000000802 | C28: ZAMUDIO VICENTE ANTERO FERNANDO | D28: SI | E28: 38901 | F28: Empleado Puesto de Control | G28: Control y Monitoreo | H28: Control y Monitoreo | I28: LIMCMEPC
A29: 42354767 | B29: 0000000809 | C29: VALDERRAMA ALVAREZ PABLO CESAR | D29: SI | E29: 38915 | F29: Supervisor Senior de Lavanderia | G29: Lavandería | H29: División de Habitaciones (Operaciones) | I29: LIMDHSLV
A30: 09952724 | B30: 0000000834 | C30: MUCHA ROBLES ALEJANDRO CESAR | D30: SI | E30: 39128 | F30: Supervisor Senior de Control y Monitoreo | G30: Control y Monitoreo | H30: Control y Monitoreo | I30: LIMCMSCM
A31: 10093494 | B31: 0000000841 | C31: BERRU DIAZ ALEXANDER HUMBERTO | D31: SI | E31: 39206 | F31: Empleado de Lavanderia | G31: Lavandería | H31: División de Habitaciones (Operaciones) | I31: LIMDH
A32: 15356442 | B32: 0000000844 | C32: MENDIETA SOLANO WILLIAM JESUS | D32: SI | E32: 39206 | F32: Gerente de Control y Monitero | G32: Control y Monitoreo | H32: Control y Monitoreo | I32: LIMCMGCM
A33: 40263172 | B33: 0000000868 | C33: PECHING CHIONG KARINA JANET | D33: SI | E33: 39407 | F33: Gerenta de Reservas | G33: Reservas | H33: Ventas y Marketing | I33: LIMVMRES
A34: 10158051 | B34: 0000000874 | C34: FALCON PAZ JULIAN MIGUEL ANGEL | D34: SI | E34: 39448 | F34: Supervisor Senior de A&B | G34: Banquetes | H34: Alimentos y Bebidas | I34: LIMAYBBQ
A35: 43813442 | B35: 0000000952 | C35: PIPA ACEVEDO RICHARD | D35: SI | E35: 40330 | F35: Carpintero | G35: Mantenimiento | H35: Mantenimiento | I35: LIMMANTGER
A36: 09790217 | B36: 0000000982 | C36: OLIVEROS AGAMA ALEX MARIANO | D36: SI | E36: 40502 | F36: Chofer | G36: Gerencia General | H36: Gerencia General | I36: LIMGGCHO
A37: 40530952 | B37: 0000000993 | C37: CARPIO PONCE GARY ANDRES | D37: SI | E37: 40575 | F37: Bodeguero | G37: Bodegas | H37: Contraloría | I37: LIMCNTBD
A38: 40073853 | B38: 0000001005 | C38: BUENDIA LIMA NILTON HENRY | D38: SI | E38: 40640 | F38: Empleado Puesto de Control | G38: Control y Monitoreo | H38: Control y Monitoreo | I38: LIMCMEPC
A39: 41712577 | B39: 0000001044 | C39: MEJIA VELASQUEZ GONSALO | D39: SI | E39: 40833 | F39: Pintor | G39: Mantenimiento | H39: Mantenimiento | I39: LIMMANT
... A46: 45321314 | B46: 0000001382 | C46: TRUJILLO MILLA JOAN ELIZABETH | D46: SI | E46: 42313 | F46: Empleado de Limpieza | G46: Limpieza | H46: División de Habitaciones (Operaciones) | I46: LIMDH
...

Sheet InventarioSwiss
G2: Inventario Equipos TI
AO4: 6 | AP4: 7 | AQ4: 8
B5: Item | C5: Fecha | D5: Pedido | E5: Orden de Compra | F5: GR - Movistar | G5: Equipo | H5: Tipo | I5: Marca | J5: Modelo | K5: S/N | L5: P/N | M5: Operador | N5: Linea | O5: IMEI1 | P5: IMEI2 | Q5: Cuenta Gmail | R5: Clave Gmail | S5: Mac Address | T5: Mac Address - Wifi | U5: IP | V5: Nombre Host | W5: Nuevo Nombre Host | X5: Procesador | Y5: Generación Procesador | Z5: Chip Video | AA5: Ram | AB5: Ram Actual | AC5: Almacenamiento | AD5: Pantalla | AE5: Sistema Operativo | AF5: Antivirus | AG5: Office | AH5: Fech. Ini Garantía | AI5: Fech. Fin Garantía | AJ5: Propiedad | AK5: Estado | AL5: DNI | AM5: Código | AN5: Usuario | AO5: Cargo | AP5: Centro de Costo | AQ5: Unidad | AR5: Observación
B6: 1 | G6: Laptop | H6: Usuario | I6: HP | J6: Notebook HP -15 | K6: CND8322H3N | L6: 3PX38LA | S6: 50-91-E3-FC-3F-ED | T6: D0-C5-D3-21-1D-29 | U6: 10.72.10.168 | V6: LIMIT01 | X6: Intel Core i7 | Y6: 8va Gen. | Z6: NVIDEA | AA6: 32 GB DDR4 | AC6: 480 GB SSD | AD6: 15" | AE6: Windows 11 Pro | AF6: Pendiente | AG6: MS Office 2007 HB | AH6: 44927 | AJ6: HOTELERA COSTA DEL PACIFICO | AK6: Operativo | AL6: 43488382 | AM6: =VLOOKUP(AL6,Personal!$A$2:$I$300,2,FALSE) -> 0000001736 | AN6: =VLOOKUP(AL6,Personal!$A$2:$I$300,3,FALSE) -> SALINAS TORRES NOE | AO6: =VLOOKUP(AL6,Personal!$A$2:$I$300,6,FALSE) -> Analista de Sistemas | AP6: =VLOOKUP(AL6,Personal!$A$2:$I$300,7,FALSE) -> Tecnologias de Información | AQ6: =VLOOKUP(AL6,Personal!$A$2:$I$300,8,FALSE) -> Tecnologias de Información
B7: 2 | G7: Monitor | H7: Usuario | I7: Samsung | J7: S27E370D | K7: 0NWEHTHH600028Y | AD7: 27" | AJ7: HOTELERA COSTA DEL PACIFICO | AK7: Operativo | AL7: 43488382 | AM7: =VLOOKUP(AL7,Personal!$A$2:$I$300,2,FALSE) -> 0000001736 | AN7: =VLOOKUP(AL7,Personal!$A$2:$I$300,3,FALSE) -> SALINAS TORRES NOE | AO7: =VLOOKUP(AL7,Personal!$A$2:$I$300,6,FALSE) -> Analista de Sistemas | AP7: =VLOOKUP(AL7,Personal!$A$2:$I$300,7,FALSE) -> Tecnologias de Información | AQ7: =VLOOKUP(AL7,Personal!$A$2:$I$300,8,FALSE) -> Tecnologias de Información
B8: 3 | G8: Parlantes | H8: Usuario | I8: Samsung | J8: HW-J250 | K8: 0BE814MJ200528E | AJ8: HOTELERA COSTA DEL PACIFICO | AK8: Operativo | AL8: 43488382 | AM8: =VLOOKUP(AL8,Personal!$A$2:$I$300,2,FALSE) -> 0000001736 | AN8: =VLOOKUP(AL8,Personal!$A$2:$I$300,3,FALSE) -> SALINAS TORRES NOE | AO8: =VLOOKUP(AL8,Personal!$A$2:$I$300,6,FALSE) -> Analista de Sistemas | AP8: =VLOOKUP(AL8,Personal!$A$2:$I$300,7,FALSE) -> Tecnologias de Información | AQ8: =VLOOKUP(AL8,Personal!$A$2:$I$300,8,FALSE) -> Tecnologias de Información
B9: 4 | G9: Celular | H9: Usuario | I9: ZTE | J9: ZTE Blade A55 | K9: LZ0A55PEDC8002023 | M9: Movistar | N9: 965647947 | O9: 860590070432272 | T9: 54-1F-8D-A0-17-C3 | X9: Movil | AA9: 4GB | AC9: 128 GB | AD9: 6.75" | AE9: Android | AJ9: HOTELERA COSTA DEL PACIFICO | AK9: Operativo | AL9: 10158051 | AM9: =VLOOKUP(AL9,Personal!$A$2:$I$300,2,FALSE) -> 0000000874 | AN9: =VLOOKUP(AL9,Personal!$A$2:$I$300,3,FALSE) -> FALCON PAZ JULIAN MIGUEL ANGEL | AO9: =VLOOKUP(AL9,Personal!$A$2:$I$300,6,FALSE) -> Supervisor Senior de A&B | AP9: =VLOOKUP(AL9,Personal!$A$2:$I$300,7,FALSE) -> Banquetes | AQ9: =VLOOKUP(AL9,Personal!$A$2:$I$300,8,FALSE) -> Alimentos y Bebidas
B10: 5 | G10: Laptop | H10: Usuario | I10: Toshiba | J10: PORTEGE-R930-SP3256KL | K10: YD039184H | L10: PT331P-0KW0GT | S10: B8-6B-23-AD-0C-20 | T10: B4-B6-76-FB-46-4F | X10: Intel Core i5 | Y10: 3era Gen. | Z10: Intel Integrado | AA10: 8 GB DDR3 | AC10: 500 GB HDD | AD10: 14" | AE10: Windows 11 Pro | AF10: Pendiente | AJ10: HOTELERA COSTA DEL PACIFICO | AK10: Custodia - Operativo | AL10: Sistemas | AM10: =VLOOKUP(AL10,Personal!$A$2:$I$300,2,FALSE) -> 0 | AN10: =VLOOKUP(AL10,Personal!$A$2:$I$300,3,FALSE) -> Tecnologias de Información | AO10: =VLOOKUP(AL10,Personal!$A$2:$I$300,6,FALSE) -> Tecnologias de Información | AP10: =VLOOKUP(AL10,Personal!$A$2:$I$300,7,FALSE) -> Tecnologias de Información | AQ10: =VLOOKUP(AL10,Personal!$A$2:$I$300,8,FALSE) -> Tecnologias de Información | AR10: Falta cover que tapa la memoria ram.
B11: 6 | G11: PC | H11: Usuario | I11: Lenovo | J11: Thinkcentre Neo 50S | K11: YLT1642S | L11: 12XG0015LS | U11: 10.72.10.177 | W11: LIMCNTSC | X11: Intel Core i7 | Y11: 14va Gen. | Z11: Intel Integrado | AA11: 16 GB DDR5 | AC11: 480 GB SSD | AE11: Windows 11 Pro | AF11: Si | AG11: MS Office 365 HB | AJ11: HOTELERA COSTA DEL PACIFICO | AK11: Operativo | AL11: 10590738 | AM11: =VLOOKUP(AL11,Personal!$A$2:$I$300,2,FALSE) -> 0 | AN11: =VLOOKUP(AL11,Personal!$A$2:$I$300,3,FALSE) -> ALVARADO CHAVARRY JIMMY GERARDO | AO11: =VLOOKUP(AL11,Personal!$A$2:$I$300,6,FALSE) -> Sub Contralor | AP11: =VLOOKUP(AL11,Personal!$A$2:$I$300,7,FALSE) -> Contabilidad | AQ11: =VLOOKUP(AL11,Personal!$A$2:$I$300,8,FALSE) -> Contraloría
B12: 7 | G12: PC | H12: Usuario | I12: Lenovo | J12: Thinkcentre Neo 50S | K12: YLT16443 | L12: 12XG0015LS | S12: D0-F4-05-3E-74-C1 | T12: E4-1F-D5-E8-9F-CC | U12: 10.72.10.146 | W12: LIMFD02 | X12: Intel Core i7 | Y12: 14va Gen. | Z12: Intel Integrado | AA12: 32 GB DDR5 | AC12: 1000 GB SSD | AE12: Windows 11 Pro | AF12: Si | AG12: MS Office 2007 HB | AJ12: HOTELERA COSTA DEL PACIFICO | AK12: Operativo | AL12: Front Desk 2 | AM12: =VLOOKUP(AL12,Personal!$A$2:$I$300,2,FALSE) -> Front Desk | AN12: =VLOOKUP(AL12,Personal!$A$2:$I$300,3,FALSE) -> Front Desk 2 | AO12: =VLOOKUP(AL12,Personal!$A$2:$I$300,6,FALSE) -> Recepcionista | AP12: =VLOOKUP(AL12,Personal!$A$2:$I$300,7,FALSE) -> Recepción | AQ12: =VLOOKUP(AL12,Personal!$A$2:$I$300,8,FALSE) -> División de Habitaciones (Operaciones) | AR12: Para Front Desk
B13: 8 | G13: PC | H13: Usuario | I13: Dell | J13: Optiplex 3020 | K13: 355VN22 | L13: 0WMJ54 | U13: 10.72.10.162 | W13: LIMVMVEN14 | X13: Intel Core i5 | Y13: 5ta Gen. | Z13: Intel Integrado | AA13: 12 GB DDR3 | AC13: 480 GB SSD | AE13: Windows 11 Pro | AF13: Si | AG13: MS Office 2007 HB | AH13: 41926 | AJ13: HOTELERA COSTA DEL PACIFICO | AK13: Operativo | AL13: 74129212 | AM13: =VLOOKUP(AL13,Personal!$A$2:$I$300,2,FALSE) -> 0000P00764 | AN13: =VLOOKUP(AL13,Personal!$A$2:$I$300,3,FALSE) -> VIDAL TAPIA ARIANA FERNANDA VALERIA | AO13: =VLOOKUP(AL13,Personal!$A$2:$I$300,6,FALSE) -> Practicante de Ventas y Marketing | AP13: =VLOOKUP(AL13,Personal!$A$2:$I$300,7,FALSE) -> Ventas | AQ13: =VLOOKUP(AL13,Personal!$A$2:$I$300,8,FALSE) -> Ventas y Marketing | AR13: Equipo con etiqueta de Finanzas
B14: 9 | G14: PC | H14: Usuario | I14: Dell | J14: Optiplex 3020 | K14: D08SN22 | L14: 0WMJ54 | U14: 10.72.10.173 | W14: LIMVMAC | X14: Intel Core i5 | Y14: 5ta Gen. | Z14: Intel Integrado | AA14: 8 GB DDR3 | AC14: 480 GB SSD | AE14: Windows 11 Pro | AF14: Si | AG14: MS Office 2007 HB | AH14: 41923 | AJ14: HOTELERA COSTA DEL PACIFICO | AK14: Operativo | AL14: 75173008 | AM14: =VLOOKUP(AL14,Personal!$A$2:$I$300,2,FALSE) -> 0000001577 | AN14: =VLOOKUP(AL14,Personal!$A$2:$I$300,3,FALSE) -> RAFAELO LORENZO ANA ROSA | AO14: =VLOOKUP(AL14,Personal!$A$2:$I$300,6,FALSE) -> Asistente de Coordinación | AP14: =VLOOKUP(AL14,Personal!$A$2:$I$300,7,FALSE) -> Ventas | AQ14: =VLOOKUP(AL14,Personal!$A$2:$I$300,8,FALSE) -> Ventas y Marketing
B15: 10 | G15: PC | H15: Usuario | I15: Dell | J15: Optiplex 3020 | K15: CZZFN22 | L15: 0WMJ54 | U15: 10.72.10.129 | W15: LIMCNTCONT8 | X15: Intel Core i5 | Y15: 5ta Gen. | Z15: Intel Integrado | AA15: 16 GB DDR3 | AC15: 480 GB SSD | AE15: Windows 11 Pro | AF15: Si | AH15: 41923 | AJ15: HOTELERA COSTA DEL PACIFICO | AK15: Operativo | AL15: 76644092 | AM15: =VLOOKUP(AL15,Personal!$A$2:$I$300,2,FALSE) -> 0000P00758 | AN15: =VLOOKUP(AL15,Personal!$A$2:$I$300,3,FALSE) -> MILLA GOMEZ ANJALI ABIGAIL | AO15: =VLOOKUP(AL15,Personal!$A$2:$I$300,6,FALSE) -> Practicante de Contabilidad | AP15: =VLOOKUP(AL15,Personal!$A$2:$I$300,7,FALSE) -> Contabilidad | AQ15: =VLOOKUP(AL15,Personal!$A$2:$I$300,8,FALSE) -> Contraloría
B16: 11 | G16: PC | H16: Servidor | I16: Dell | J16: Optiplex 3020 | K16: D0DHN22 | L16: 0WMJ54 | S16: B0-83-FE-5E-0A-B9 | U16: 10.72.8.115 | W16: LIMH1SVRCONAC | X16: Intel Core i5 | Y16: 5ta Gen. | Z16: Intel Integrado | AA16: 12 GB DDR3 | AC16: 480 GB SSD | AE16: Windows 11 Pro | AF16: Si | AG16: MS Office 2007 HB | AH16: 41923 | AJ16: HOTELERA COSTA DEL PACIFICO | AK16: Operativo | AL16: Sistemas | AM16: =VLOOKUP(AL16,Personal!$A$2:$I$300,2,FALSE) -> 0 | AN16: =VLOOKUP(AL16,Personal!$A$2:$I$300,3,FALSE) -> Tecnologias de Información | AO16: =VLOOKUP(AL16,Personal!$A$2:$I$300,6,FALSE) -> Tecnologias de Información | AP16: =VLOOKUP(AL16,Personal!$A$2:$I$300,7,FALSE) -> Tecnologias de Información | AQ16: =VLOOKUP(AL16,Personal!$A$2:$I$300,8,FALSE) -> Tecnologias de Información | AR16: Integrador Contastec con Opera Cloud - FACT. ELECT
B17: 12 | G17: PC | H17: Usuario | I17: Dell | J17: Optiplex 3020 | K17: CZNGN22 | L17: 0WMJ54 | AH17: 41923 | AJ17: HOTELERA COSTA DEL PACIFICO | AK17: Custodia - Por Revisar | AL17: Sistemas | AM17: =VLOOKUP(AL17,Personal!$A$2:$I$300,2,FALSE) -> 0 | AN17: =VLOOKUP(AL17,Personal!$A$2:$I$300,3,FALSE) -> Tecnologias de Información | AO17: =VLOOKUP(AL17,Personal!$A$2:$I$300,6,FALSE) -> Tecnologias de Información | AP17: =VLOOKUP(AL17,Personal!$A$2:$I$300,7,FALSE) -> Tecnologias de Información | AQ17: =VLOOKUP(AL17,Personal!$A$2:$I$300,8,FALSE) -> Tecnologias de Información
B18: 13 | G18: PC | H18: Usuario | I18: Dell | J18: Optiplex 3020 | K18: D1BGN22 | L18: 0WMJ54 | X18: Intel Core i5 | Y18: 5ta Gen. | Z18: Intel Integrado | AF18: Pendiente | AH18: 41925 | AJ18: HOTELERA COSTA DEL PACIFICO | AK18: Custodia - Por Revisar | AL18: Sistemas | AM18: =VLOOKUP(AL18,Personal!$A$2:$I$300,2,FALSE) -> 0 | AN18: =VLOOKUP(AL18,Personal!$A$2:$I$300,3,FALSE) -> Tecnologias de Información | AO18: =VLOOKUP(AL18,Personal!$A$2:$I$300,6,FALSE) -> Tecnologias de Información | AP18: =VLOOKUP(AL18,Personal!$A$2:$I$300,7,FALSE) -> Tecnologias de Información | AQ18: =VLOOKUP(AL18,Personal!$A$2:$I$300,8,FALSE) -> Tecnologias de Información
B19: 14 | G19: PC | H19: Usuario | I19: Dell | J19: Optiplex 3020 | K19: D1BSN22 | L19: 0WMJ54 | S19: B0-83-FE-55-28-CD | U19: 10.72.10.109 | W19: LIMCMSCM01 | X19: Intel Core i5 | Y19: 5ta Gen. | Z19: Intel Integrado | AA19: 16 GB DDR3 | AC19: 480 GB SSD | AE19: Windows 11 Pro | AF19: Si | AH19: 41923 | AJ19: HOTELERA COSTA DEL PACIFICO | AK19: Operativo | AL19: CyM | AM19: =VLOOKUP(AL19,Personal!$A$2:$I$300,2,FALSE) -> 0 | AN19: =VLOOKUP(AL19,Personal!$A$2:$I$300,3,FALSE) -> Control y Monitoreo | AO19: =VLOOKUP(AL19,Personal!$A$2:$I$300,6,FALSE) -> Empleado Puesto de Control | AP19: =VLOOKUP(AL19,Personal!$A$2:$I$300,7,FALSE) -> Control y Monitoreo | AQ19: =VLOOKUP(AL19,Personal!$A$2:$I$300,8,FALSE) -> Control y Monitoreo
B20: 15 | G20: PC | H20: Usuario | I20: Dell | J20: Optiplex 3020 | K20: D00RN22 | L20: 0WMJ54 | S20: B0-83-FE-5E-E5-BC | U20: 10.72.10.103 | W20: LIMAYBSGER | X20: Intel Core i5 | Y20: 5ta Gen. | Z20: Intel Integrado | AA20: 16 GB DDR3 | AC20: 480 GB SSD | AE20: Windows 11 Pro | AF20: Si | AG20: MS Office 365 HB | AH20: 41923 | AJ20: HOTELERA COSTA DEL PACIFICO | AK20: Operativo | AL20: 10479259 | AM20: =VLOOKUP(AL20,Personal!$A$2:$I$300,2,FALSE) -> 0000000031 | AN20: =VLOOKUP(AL20,Personal!$A$2:$I$300,3,FALSE) -> MEDINA CASTILLO ALVARO GERARDO | AO20: =VLOOKUP(AL20,Personal!$A$2:$I$300,6,FALSE) -> Sub Gerente de A&B | AP20: =VLOOKUP(AL20,Personal!$A$2:$I$300,7,FALSE) -> Gerencia A&B | AQ20: =VLOOKUP(AL20,Personal!$A$2:$I$300,8,FALSE) -> Alimentos y Bebidas
B21: 16 | G21: PC | H21: Usuario | I21: Dell | J21: Optiplex 3020 | K21: D04SN22 | L21: 0WMJ54 | U21: 10.72.10.120 | W21: LIMSMGCC | X21: Intel Core i5 | Y21: 5ta Gen. | Z21: Intel Integrado | AA21: 16 GB DDR3 | AC21: 480 GB SSD | AE21: Windows 11 Pro | AF21: Si | AG21: MS Office 2007 HB | AH21: 41923 | AJ21: HOTELERA COSTA DEL PACIFICO | AK21: Operativo | AL21: 40235456 | AM21: =VLOOKUP(AL21,Personal!$A$2:$I$300,2,FALSE) -> 0000000806 | AN21: =VLOOKUP(AL21,Personal!$A$2:$I$300,3,FALSE) -> TRUJILLO GARAY MONICA ALEJANDRA | AO21: =VLOOKUP(AL21,Personal!$A$2:$I$300,6,FALSE) -> Gerente de Congresos y Convenciones | AP21: =VLOOKUP(AL21,Personal!$A$2:$I$300,7,FALSE) -> Ventas | AQ21: =VLOOKUP(AL21,Personal!$A$2:$I$300,8,FALSE) -> Ventas y Marketing
B22: 17 | G22: PC | H22: Usuario | I22: Dell | J22: Optiplex 3020 | K22: GK1TN22 | L22: 0WMJ54 | X22: Intel Core i5 | Y22: 5ta Gen. | Z22: Intel Integrado | AA22: 16 GB DDR3 | AE22: Windows 11 Pro | AF22: Pendiente | AH22: 41925 | AJ22: HOTELERA COSTA DEL PACIFICO | AK22: Custodia - Operativo | AL22: Sistemas | AM22: =VLOOKUP(AL22,Personal!$A$2:$I$300,2,FALSE) -> 0 | AN22: =VLOOKUP(AL22,Personal!$A$2:$I$300,3,FALSE) -> Tecnologias de Información | AO22: =VLOOKUP(AL22,Personal!$A$2:$I$300,6,FALSE) -> Tecnologias de Información | AP22: =VLOOKUP(AL22,Personal!$A$2:$I$300,7,FALSE) -> Tecnologias de Información | AQ22: =VLOOKUP(AL22,Personal!$A$2:$I$300,8,FALSE) -> Tecnologias de Información | AR22: Para asignar Ventas
B23: 18 | G23: Tablet | H23: Usuario | I23: Lenovo | J23: A7600-F | K23: HJH0ATGD | T23: 60-D9-A0-20-3A7F | X23: Movil | AA23: 1GB | AC23: 16 GB | AD23: 10" | AE23: Android | AF23: N/A | AJ23: HOTELERA COSTA DEL PACIFICO | AK23: Custodia - Obsoleto | AL23: Sistemas | AM23: =VLOOKUP(AL23,Personal!$A$2:$I$300,2,FALSE) -> 0 | AN23: =VLOOKUP(AL23,Personal!$A$2:$I$300,3,FALSE) -> Tecnologias de Información | AO23: =VLOOKUP(AL23,Personal!$A$2:$I$300,6,FALSE) -> Tecnologias de Información | AP23: =VLOOKUP(AL23,Personal!$A$2:$I$300,7,FALSE) -> Tecnologias de Información | AQ23: =VLOOKUP(AL23,Personal!$A$2:$I$300,8,FALSE) -> Tecnologias de Información | AR23: SIN CARGADOR
B24: 19 | G24: PC | H24: Usuario | I24: Gigabyte | J24: GB-BSi3H-6100 | K24: 1601631981 | X24: Intel Core i3 | Y24: 6ta Gen. | Z24: Intel Integrado | AA24: 8 GB DDR3 | AC24: 480 GB SSD | AE24: Windows 11 Pro | AF24: Pendiente | AJ24: HOTELERA COSTA DEL PACIFICO | AK24: Custodia - Operativo | AL24: Sistemas | AM24: =VLOOKUP(AL24,Personal!$A$2:$I$300,2,FALSE) -> 0 | AN24: =VLOOKUP(AL24,Personal!$A$2:$I$300,3,FALSE) -> Tecnologias de Información | AO24: =VLOOKUP(AL24,Personal!$A$2:$I$300,6,FALSE) -> Tecnologias de Información | AP24: =VLOOKUP(AL24,Personal!$A$2:$I$300,7,FALSE) -> Tecnologias de Información | AQ24: =VLOOKUP(AL24,Personal!$A$2:$I$300,8,FALSE) -> Tecnologias de Información | AR24: SE USARA PARA CLONACION DE IMÁGENES WINDOWS
B25: 20 | G25: PC | H25: Usuario | I25: Gigabyte | J25: GB-BSi3H-6100 | K25: 1601631938 | X25: Intel Core i3 | Y25: 6ta Gen. | Z25: Intel Integrado | AJ25: HOTELERA COSTA DEL PACIFICO | AK25: Custodia - Por Revisar | AL25: Sistemas | AM25: =VLOOKUP(AL25,Personal!$A$2:$I$300,2,FALSE) -> 0 | AN25: =VLOOKUP(AL25,Personal!$A$2:$I$300,3,FALSE) -> Tecnologias de Información | AO25: =VLOOKUP(AL25,Personal!$A$2:$I$300,6,FALSE) -> Tecnologias de Información | AP25: =VLOOKUP(AL25,Personal!$A$2:$I$300,7,FALSE) -> Tecnologias de Información | AQ25: =VLOOKUP(AL25,Personal!$A$2:$I$300,8,FALSE) -> Tecnologias de Información
B26: 21 | G26: PC | H26: Usuario | I26: Lenovo | J26: Thinkcentre Neo 50S | K26: YLT16FYF | L26: 12XG0015LS | S26: D0-F4-05-3F-CC-11 | T26: 9C-67-D6-78-99-A2 | X26: Intel Core i7 | Y26: 14va Gen. | Z26: Intel Integrado | AA26: 32 GB DDR3 | AC26: 1000 GB SSD | AE26: Windows 11 Pro | AF26: Pendiente | AJ26: HOTELERA COSTA DEL PACIFICO | AK26: Custodia - Operativo | AL26: Sistemas | AM26: =VLOOKUP(AL26,Personal!$A$2:$I$300,2,FALSE) -> 0 | AN26: =VLOOKUP(AL26,Personal!$A$2:$I$300,3,FALSE) -> Tecnologias de Información | AO26: =VLOOKUP(AL26,Personal!$A$2:$I$300,6,FALSE) -> Tecnologias de Información | AP26: =VLOOKUP(AL26,Personal!$A$2:$I$300,7,FALSE) -> Tecnologias de Información | AQ26: =VLOOKUP(AL26,Personal!$A$2:$I$300,8,FALSE) -> Tecnologias de Información | AR26: Para Contabilidad
B27: 22 | G27: PC | H27: Usuario | I27: Toshiba | J27: PORTEGE-R930-SP3256KL | K27: YD039215H | L27: PT331P-0KW0GT | X27: Intel Core i5 | Y27: 3era Gen. | Z27: Intel Integrado | AF27: N/A | AJ27: HOTELERA COSTA DEL PACIFICO | AK27: Custodia - Inoperativo | AL27: Sistemas | AM27: =VLOOKUP(AL27,Personal!$A$2:$I$300,2,FALSE) -> 0 | AN27: =VLOOKUP(AL27,Personal!$A$2:$I$300,3,FALSE) -> Tecnologias de Información | AO27: =VLOOKUP(AL27,Personal!$A$2:$I$300,6,FALSE) -> Tecnologias de Información | AP27: =VLOOKUP(AL27,Personal!$A$2:$I$300,7,FALSE) -> Tecnologias de Información | AQ27: =VLOOKUP(AL27,Personal!$A$2:$I$300,8,FALSE) -> Tecnologias de Información
B28: 23 | G28: PC | H28: Usuario | I28: Lenovo | J28: Thinkcentre Neo 50S | K28: YLT1643J | L28: 12XG0015LS | S28: D0-F4-05-3E-74-BB | U28: 10.72.10.34 | W28: LIMFD01 | X28: Intel Core i7 | Y28: 14va Gen. | Z28: Intel Integrado | AA28: 32 GB DDR5 | AC28: 1000 GB SSD | AE28: Windows 11 Pro | AF28: Si | AG28: MS Office 2007 HB | AJ28: HOTELERA COSTA DEL PACIFICO | AK28: Operativo | AL28: Front Desk 1 | AM28: =VLOOKUP(AL28,Personal!$A$2:$I$300,2,FALSE) -> Front Desk | AN28: =VLOOKUP(AL28,Personal!$A$2:$I$300,3,FALSE) -> Front Desk 1 | AO28: =VLOOKUP(AL28,Personal!$A$2:$I$300,6,FALSE) -> Recepcionista | AP28: =VLOOKUP(AL28,Personal!$A$2:$I$300,7,FALSE) -> Recepción | AQ28: =VLOOKUP(AL28,Personal!$A$2:$I$300,8,FALSE) -> División de Habitaciones (Operaciones) | AR28: Para Front Desk
B29: 24 | G29: Monitor | H29: Usuario | I29: Dell | J29: E2014HC | K29: CN012MWY6418046P3JJU | AD29: 20" | AJ29: HOTELERA COSTA DEL PACIFICO | AK29: Operativo | AL29: 09692690 | AM29: =VLOOKUP(AL29,Personal!$A$2:$I$300,2,FALSE) -> 0000000269 | AN29: =VLOOKUP(AL29,Personal!$A$2:$I$300,3,FALSE) -> VEGA ARRATEA JAVIER VICTOR | AO29: =VLOOKUP(AL29,Personal!$A$2:$I$300,6,FALSE) -> Supervisor Jr. de Steward | AP29: =VLOOKUP(AL29,Personal!$A$2:$I$300,7,FALSE) -> Steward | AQ29: =VLOOKUP(AL29,Personal!$A$2:$I$300,8,FALSE) -> Alimentos y Bebidas
B30: 25 | G30: Monitor | H30: Usuario | I30: Dell | J30: E2014HC | K30: CN012MWY6418046P3P7U | AD30: 20" | AJ30: HOTELERA COSTA DEL PACIFICO | AK30: Custodia - Operativo | AL30: Sistemas | AM30: =VLOOKUP(AL30,Personal!$A$2:$I$300,2,FALSE) -> 0 | AN30: =VLOOKUP(AL30,Personal!$A$2:$I$300,3,FALSE) -> Tecnologias de Información | AO30: =VLOOKUP(AL30,Personal!$A$2:$I$300,6,FALSE) -> Tecnologias de Información | AP30: =VLOOKUP(AL30,Personal!$A$2:$I$300,7,FALSE) -> Tecnologias de Información | AQ30: =VLOOKUP(AL30,Personal!$A$2:$I$300,8,FALSE) -> Tecnologias de Información
B31: 26 | G31: Monitor | H31: Usuario | I31: Samsung | J31: DB22D-P | K31: 03AMHCJJ100119B | AD31: 22" | AJ31: HOTELERA COSTA DEL PACIFICO | AK31: Custodia - Operativo | AL31: Sistemas | AM31: =VLOOKUP(AL31,Personal!$A$2:$I$300,2,FALSE) -> 0 | AN31: =VLOOKUP(AL31,Personal!$A$2:$I$300,3,FALSE) -> Tecnologias de Información | AO31: =VLOOKUP(AL31,Personal!$A$2:$I$300,6,FALSE) -> Tecnologias de Información | AP31: =VLOOKUP(AL31,Personal!$A$2:$I$300,7,FALSE) -> Tecnologias de Información | AQ31: =VLOOKUP(AL31,Personal!$A$2:$I$300,8,FALSE) -> Tecnologias de Información
B32: 27 | G32: PC | H32: Usuario | I32: HP | K32: MXL4321BG8 | X32: Intel Core i5 | Y32: 4ta Gen. | Z32: Intel Integrado | AA32: 16 GB DDR3 | AC32: 480 GB SSD | AE32: Windows 11 Pro | AF32: Si | AJ32: HOTELERA COSTA DEL PACIFICO | AK32: Custodia - Operativo | AL32: Sistemas | AM32: =VLOOKUP(AL32,Personal!$A$2:$I$300,2,FALSE) -> 0 | AN32: =VLOOKUP(AL32,Personal!$A$2:$I$300,3,FALSE) -> Tecnologias de Información | AO32: =VLOOKUP(AL32,Personal!$A$2:$I$300,6,FALSE) -> Tecnologias de Información | AP32: =VLOOKUP(AL32,Personal!$A$2:$I$300,7,FALSE) -> Tecnologias de Información | AQ32: =VLOOKUP(AL32,Personal!$A$2:$I$300,8,FALSE) -> Tecnologias de Información
B33: 28 | G33: Impresora | H33: Usuario | I33: Sharp | J33: MX-3070V | K33: 3500930400 | S33: A4:D7:3C:6F:E2:D0 | U33: 10.72.8.200 | V33: EPSON6FE2D0 | AJ33: Prov. DATACONT | AK33: Operativo | AM33: =VLOOKUP(AL33,Personal!$A$2:$I$300,2,FALSE) -> #N/A | AN33: =VLOOKUP(AL33,Personal!$A$2:$I$300,3,FALSE) -> #N/A | AO33: =VLOOKUP(AL33,Personal!$A$2:$I$300,6,FALSE) -> #N/A | AP33: =VLOOKUP(AL33,Personal!$A$2:$I$300,7,FALSE) -> #N/A | AQ33: =VLOOKUP(AL33,Personal!$A$2:$I$300,8,FALSE) -> #N/A | AR33: 1er Sotano - RRHH - Sistemas
B34: 29 | G34: Impresora | H34: Usuario | I34: Epson | J34: WF-C5790 Series | K34: X3B7003661 | S34: 9C:AE:D3:AD:20:FE | U34: 10.72.8.132 | V34: EPSONAD20FE | AJ34: Prov. DATACONT | AK34: Operativo | AM34: =VLOOKUP(AL34,Personal!$A$2:$I$300,2,FALSE) -> #N/A | AN34: =VLOOKUP(AL34,Personal!$A$2:$I$300,3,FALSE) -> #N/A | AO34: =VLOOKUP(AL34,Personal!$A$2:$I$300,6,FALSE) -> #N/A | AP34: =VLOOKUP(AL34,Personal!$A$2:$I$300,7,FALSE) -> #N/A | AQ34: =VLOOKUP(AL34,Personal!$A$2:$I$300,8,FALSE) -> #N/A | AR34: 1er Sotano - Steward - Limpieza
B35: 30 | G35: Impresora | H35: Usuario | I35: Epson | J35: WF-C5890 Series | K35: XBJZ017266 | S35: A4:D7:3C:6F:E1:2A | U35: 10.72.8.229 | V35: EPSON6FE12A | AJ35: Prov. DATACONT | AK35: Operativo | AM35: =VLOOKUP(AL35,Personal!$A$2:$I$300,2,FALSE) -> #N/A | AN35: =VLOOKUP(AL35,Personal!$A$2:$I$300,3,FALSE) -> #N/A | AO35: =VLOOKUP(AL35,Personal!$A$2:$I$300,6,FALSE) -> #N/A | AP35: =VLOOKUP(AL35,Personal!$A$2:$I$300,7,FALSE) -> #N/A | AQ35: =VLOOKUP(AL35,Personal!$A$2:$I$300,8,FALSE) -> #N/A | AR35: 1er Sotano - Housekeeping
B36: 31 | G36: Impresora | H36: Usuario | I36: Epson | J36: WF-C5890 Series | K36: XBJZ021772 | S36: A4:D7:3C:70:EE:9C | U36: 10.72.8.151 | AJ36: Prov. DATACONT | AK36: Operativo | AM36: =VLOOKUP(AL36,Personal!$A$2:$I$300,2,FALSE) -> #N/A | AN36: =VLOOKUP(AL36,Personal!$A$2:$I$300,3,FALSE) -> #N/A | AO36: =VLOOKUP(AL36,Personal!$A$2:$I$300,6,FALSE) -> #N/A | AP36: =VLOOKUP(AL36,Personal!$A$2:$I$300,7,FALSE) -> #N/A | AQ36: =VLOOKUP(AL36,Personal!$A$2:$I$300,8,FALSE) -> #N/A | AR36: 3er Piso - Gerencia General
B37: 32 | G37: Impresora | H37: Usuario | I37: Epson | J37: WF-C5890 Series | K37: XBJZ027512 | S37: A4:D7:3C:72:F2:76 | U37: 10.72.8.210 | V37: EPSON72F276 | AJ37: Prov. DATACONT | AK37: Operativo | AM37: =VLOOKUP(AL37,Personal!$A$2:$I$300,2,FALSE) -> #N/A | AN37: =VLOOKUP(AL37,Personal!$A$2:$I$300,3,FALSE) -> #N/A | AO37: =VLOOKUP(AL37,Personal!$A$2:$I$300,6,FALSE) -> #N/A | AP37: =VLOOKUP(AL37,Personal!$A$2:$I$300,7,FALSE) -> #N/A | AQ37: =VLOOKUP(AL37,Personal!$A$2:$I$300,8,FALSE) -> #N/A | AR37: 3er Piso - Ventas
B38: 33 | G38: Impresora | H38: Usuario | I38: Epson | J38: WF-C5790 Series | K38: X3B7003659 | S38: 9C:AE:D3:AD:21:00 | U38: 10.72.8.197 | V38: EPSONAD2100 | AJ38: Prov. DATACONT | AK38: Operativo | AM38: =VLOOKUP(AL38,Personal!$A$2:$I$300,2,FALSE) -> #N/A | AN38: =VLOOKUP(AL38,Personal!$A$2:$I$300,3,FALSE) -> #N/A | AO38: =VLOOKUP(AL38,Personal!$A$2:$I$300,6,FALSE) -> #N/A | AP38: =VLOOKUP(AL38,Personal!$A$2:$I$300,7,FALSE) -> #N/A | AQ38: =VLOOKUP(AL38,Personal!$A$2:$I$300,8,FALSE) -> #N/A | AR38: 3er Piso - Reservas
B39: 34 | G39: Impresora | H39: Usuario | I39: Epson | J39: WF-C5790 Series | K39: X3B7003703 | S39: 9C:AE:D3:AD:20:F0 | U39: 10.9.10.153 | V39: EPSONAD20F0 | AJ39: Prov. DATACONT | AK39: Operativo | AM39: =VLOOKUP(AL39,Personal!$A$2:$I$300,2,FALSE) -> #N/A | AN39: =VLOOKUP(AL39,Personal!$A$2:$I$300,3,FALSE) -> #N/A | AO39: =VLOOKUP(AL39,Personal!$A$2:$I$300,6,FALSE) -> #N/A | AP39: =VLOOKUP(AL39,Personal!$A$2:$I$300,7,FALSE) -> #N/A | AQ39: =VLOOKUP(AL39,Personal!$A$2:$I$300,8,FALSE) -> #N/A | AR39: 1er Piso Gym
B40: 35 | G40: Impresora | H40: Usuario | I40: Epson | J40: WF-C5790 Series | K40: X3B7002433 | S40: 9C:AE:D3:AC:4D:78 | U40: 10.72.8.191 | V40: EPSONAC4D78 | AJ40: Prov. DATACONT | AK40: Operativo | AM40: =VLOOKUP(AL40,Personal!$A$2:$I$300,2,FALSE) -> #N/A | AN40: =VLOOKUP(AL40,Personal!$A$2:$I$300,3,FALSE) -> #N/A | AO40: =VLOOKUP(AL40,Personal!$A$2:$I$300,6,FALSE) -> #N/A | AP40: =VLOOKUP(AL40,Personal!$A$2:$I$300,7,FALSE) -> #N/A | AQ40: =VLOOKUP(AL40,Personal!$A$2:$I$300,8,FALSE) -> #N/A | AR40: 2do Piso - Oficina Banquetes
B41: 36 | G41: Impresora | H41: Usuario | I41: Sharp | J41: MX-M3070 | K41: 15064216 | U41: 10.72.8.203 | V41: EPSON27359D | AJ41: Prov. DATACONT | AK41: Operativo | AM41: =VLOOKUP(AL41,Personal!$A$2:$I$300,2,FALSE) -> #N/A | AN41: =VLOOKUP(AL41,Personal!$A$2:$I$300,3,FALSE) -> #N/A | AO41: =VLOOKUP(AL41,Personal!$A$2:$I$300,6,FALSE) -> #N/A | AP41: =VLOOKUP(AL41,Personal!$A$2:$I$300,7,FALSE) -> #N/A | AQ41: =VLOOKUP(AL41,Personal!$A$2:$I$300,8,FALSE) -> #N/A | AR41: 2do Piso - Seguridad
B42: 37 | G42: Impresora | H42: Usuario | I42: Canon | J42: iR1730i | K42: QFX06245 | U42: 10.72.8.215 | V42: imageRUNNER1730i | AJ42: Prov. DATACONT | AK42: Operativo | AM42: =VLOOKUP(AL42,Personal!$A$2:$I$300,2,FALSE) -> #N/A | AN42: =VLOOKUP(AL42,Personal!$A$2:$I$300,3,FALSE) -> #N/A | AO42: =VLOOKUP(AL42,Personal!$A$2:$I$300,6,FALSE) -> #N/A | AP42: =VLOOKUP(AL42,Personal!$A$2:$I$300,7,FALSE) -> #N/A | AQ42: =VLOOKUP(AL42,Personal!$A$2:$I$300,8,FALSE) -> #N/A | AR42: 2do Piso - Oficina Auditor de Ingresos
...

Sheet Dinamica
A3: Propiedad | B3: Unidad | C3: Centro de Costo | D3: Usuario | E3: Cargo | F3: Equipo | G3: Host | H3: Nombre Host | I3: IP | J3: Tipo | K3: Marca | L3: S/N | M3: Estado | N3: Ram | O3: Almacenamiento | P3: Sistema Operativo | Q3: Office | R3: Cuenta Equipos
A4: HOTELERA COSTA DEL PACIFICO | B4: Alimentos y Bebidas | C4: Banquetes | D4: FALCON PAZ JULIAN MIGUEL ANGEL | E4: Supervisor Senior de A&B | F4: PC | G4: LIMAYBBQ01 | H4: LIMH1W7P85 | I4: 10.72.10.83 | J4: Usuario | K4: Dell | L4: D04FN22 | M4: Operativo | N4: 16 GB DDR3 | O4: 480 GB SSD | P4: Windows 11 Pro | Q4: MS Office 2007 HB | R4: 1
D5: GOMEZ COBEÑA PERCY BOLIVAR | E5: Capitán de Banquetes | F5: PC | G5: LIMAYBBQ02 | H5: LIMH1W10P061 | I5: 10.72.10.100 | J5: Usuario | K5: Dell | L5: 359ZN22 | M5: Operativo | N5: 16 GB DDR3 | O5: 480 GB SSD | P5: Windows 11 Pro | Q5: MS Office 2007 HB | R5: 1
C6: Gerencia A&B | D6: JARA RISCO GINO | E6: Director de Alimentos y Bebidas | F6: PC | G6: (en blanco) | H6: LIMH1W11P071 | I6: 10.72.10.41 | J6: Usuario | K6: Dell | L6: CZPRN22 | M6: Operativo | N6: 16 GB DDR3 | O6: 480 GB SSD | P6: Windows 11 Pro | Q6: MS Office 2007 HB | R6: 1
D7: MEDINA CASTILLO ALVARO GERARDO | E7: Sub Gerente de A&B | F7: PC | G7: LIMAYBSGER | H7: (en blanco) | I7: 10.72.10.103 | J7: Usuario | K7: Dell | L7: D00RN22 | M7: Operativo | N7: 16 GB DDR3 | O7: 480 GB SSD | P7: Windows 11 Pro | Q7: MS Office 365 HB | R7: 1
D8: RAMOS MAGAN HANNA GRACE | E8: Asistente Administrativa Jr. | F8: PC | G8: LIMFB02 | H8: (en blanco) | I8: 10.72.10.93 | J8: Usuario | K8: Dell | L8: GK6DN22 | M8: Operativo | N8: 16 GB DDR3 | O8: 480 GB SSD | P8: Windows 11 Pro | Q8: MS Office 2007 HB | R8: 1
D9: ROMAN ZUÑIGA ANNIE PAOLA | E9: Gerente de Alimentos y Bebidas | F9: PC | G9: LIMAYBGER | H9: (en blanco) | I9: 10.72.10.161 | J9: Usuario | K9: Dell | L9: 356YN22 | M9: Operativo | N9: 16 GB DDR3 | O9: 480 GB SSD | P9: Windows 11 Pro | Q9: MS Office 365 HB | R9: 1
C10: La Locanda | D10: HERRERA SOLIS CLAUDIA DANIELA FELICITA | E10: Restaurant Manager | F10: PC | G10: LIMAYBLL | H10: limh1w10p011 | I10: 10.72.10.72 | J10: Usuario | K10: Dell | L10: GK2HN22 | M10: Operativo | N10: 16 GB DDR3 | O10: 480 GB SSD | P10: Windows 11 Pro | Q10: MS Office 2007 HB | R10: 1
C11: Le Café | D11: ABANTO CARRANZA ANDREA SOFIA | E11: Consejero Gastronómico | F11: PC | G11: LIMAYBLC02 | H11: limh1w10p008 | I11: 10.72.10.63 | J11: Usuario | K11: Dell | L11: D07QN22 | M11: Operativo | N11: 16 GB DDR3 | O11: 480 GB SSD | P11: Windows 11 Pro | Q11: MS Office 2007 HB | R11: 1
D12: GUTIERREZ OYARDO ANGELA GEORGINA | E12: Consejero Gastronómico | F12: PC | G12: LIMAYBLC01 | H12: (en blanco) | I12: 10.72.10.118 | J12: Usuario | K12: Dell | L12: D1FDN22 | M12: Operativo | N12: 16 GB DDR3 | O12: 480 GB SSD | P12: Windows 11 Pro | Q12: MS Office 365 HB | R12: 1
C13: Lobby | D13: UGAZ OLIVARES PALOMA | E13: Supervisor Senior de A&B | F13: PC | G13: LIMAYBLB | H13: LIMH1W7P95 | I13: 10.72.10.44 | J13: Usuario | K13: Dell | L13: 352YN22 | M13: Operativo | N13: 16 GB DDR3 | O13: 480 GB SSD | P13: Windows 11 Pro | Q13: MS Office 2007 HB | R13: 1
C14: Room Service | D14: HUAPAYA PEREZ LUIS ANGEL | E14: Supervisor de A&B | F14: PC | G14: LIMAYBRS | H14: limh1w10p005 | I14: 10.72.10.87 | J14: Usuario | K14: Dell | L14: GJVQN22 | M14: Operativo | N14: 16 GB DDR3 | O14: 480 GB SSD | P14: Windows 11 Pro | Q14: MS Office 2007 HB | R14: 1
C15: Steward | D15: VEGA ARRATEA JAVIER VICTOR | E15: Supervisor Jr. de Steward | F15: PC | G15: LIMFBSW | H15: (en blanco) | I15: 10.72.10.84 | J15: Usuario | K15: Dell | L15: GK2QN22 | M15: Operativo | N15: 16 GB DDR3 | O15: 480 GB SSD | P15: Windows 11 Pro | Q15: MS Office 2007 HB | R15: 1
C16: Piso Ejecutivo | D16: RODRIGUEZ ESPINOZA CYANE MILAGROS | E16: Consejero Gastronómico | F16: PC | G16: (en blanco) | H16: LIMH1W7P05 | I16: 10.72.10.164 | J16: Usuario | K16: HP | L16: MXL4321BFX | M16: Operativo | N16: 12 GB DDR3 | O16: 250 GB SSD | P16: Windows 11 Pro | Q16: MS Office 2007 HB | R16: 1
B17: Total Alimentos y Bebidas | R17: 13
B18: Cocina | C18: Calidad | D18: ALEGRE ANGELES FERNANDA LUCIA | E18: Jefa de Aseguramiento de Calidad | F18: PC | G18: LIMCOC06 | H18: (en blanco) | I18: (en blanco) | J18: Usuario | K18: HP | L18: 9CG6262196 | M18: Operativo | N18: 8 GB DDR4 | O18: 250 GB SSD | P18: Windows 11 Pro | Q18: MS Office 365 HB | R18: 1
D19: CONDORI MORENO ELIZABETH CINTHIA | E19: Asistente de Calidad | F19: PC | G19: LIMCOC05 | H19: (en blanco) | I19: 10.72.10.138 | J19: Usuario | K19: Dell | L19: D01GN22 | M19: Operativo | N19: 16 GB DDR3 | O19: 480 GB SSD | P19: Windows 11 Pro | Q19: MS Office 365 HB | R19: 1
C20: Cocina | D20: LOPEZ PEREZ JUAN | E20: Chef Ejecutivo | F20: PC | G20: LIMCHEF | H20: LIMH1W10FB010 | I20: 10.72.10.106 | J20: Usuario | K20: Dell | L20: D09HN22 | M20: Operativo | N20: 16 GB DDR3 | O20: 480 GB SSD | P20: Windows 11 Pro | Q20: MS Office 365 HB | R20: 1
D21: TRONCOS REQUEJO MELANIE ALICIA | E21: Practicante Administrativo de Cocina | F21: PC | G21: LIMCOC02 | H21: (en blanco) | I21: 10.72.10.49 | J21: Usuario | K21: Dell | L21: D1HFN22 | M21: Operativo | N21: 16 GB DDR3 | O21: 480 GB SSD | P21: Windows 11 Pro | Q21: MS Office 365 HB | R21: 1
C22: Cocina La Locanda | D22: BAUTISTA CARDENAS MIGUEL ALEJANDRO | E22: Sub Chef | F22: PC | G22: LIMCOC03 | H22: LIMH1W11FB12 | I22: 10.72.10.144 | J22: Usuario | K22: Dell | L22: CZNQN22 | M22: Operativo | N22: 16 GB DDR3 | O22: 250 GB SSD | P22: Windows 11 Pro | Q22: MS Office 2007 HB | R22: 1
G23: LIMCOC04 | H23: LIMH1FBPC06 | I23: 10.72.10.157 | J23: Usuario | K23: Dell | L23: CZYQN22 | M23: Operativo | N23: 16 GB DDR3 | O23: 480 GB SSD | P23: Windows 11 Pro | Q23: MS Office 2007 HB | R23: 1
C24: Pastelería | D24: CHAVEZ LING SUSANA BETSABE | E24: Supervisor Pasteleria / Panadería | F24: PC | G24: LIMCOC01 | H24: LIMH1W11FB12 | I24: 10.72.10.99 | J24: Usuario | K24: Dell | L24: 3510P22 | M24: Operativo | N24: 12 GB DDR3 | O24: 480 GB SSD | P24: Windows 11 Pro | Q24: MS Office 365 HB | R24: 1
B25: Total Cocina | R25: 7
B26: Compras | C26: Compras | D26: CASTRO MORA NELLY YOLANDA | E26: Gerente de Compras Regional | F26: Laptop | G26: LIMPU01 | H26: (en blanco) | I26: 10.72.10.101 | J26: Usuario | K26: Lenovo | L26: PF3KWH96 | M26: Operativo | N26: 16 GB DDR4 | O26: 1000 GB SSD | P26: Windows 11 Pro | Q26: MS Office 365 HB | R26: 1
D27: OBARA AVI JUAN FERNANDO | E27: Gerente de Compras | F27: PC | G27: LIMCOMPGC | H27: LIMH1PUPC001 | I27: 10.72.10.51 | J27: Usuario | K27: Dell | L27: 35CXN22 | M27: Operativo | N27: 16 GB DDR3 | O27: 480 GB SSD | P27: Windows 11 Pro | Q27: MS Office 2007 HB | R27: 1
B28: Total Compras | R28: 2
B29: Contraloría | C29: Auditoría de Ingresos | D29: MOTA CASTRO JIM EDUARDO | E29: Auditor de Ingresos | F29: PC | G29: LIMCNTAI | H29: LIMH1W7P65 | I29: 10.72.10.138 | J29: Usuario | K29: Dell | L29: D09RN22 | M29: Operativo | N29: 16 GB DDR3 | O29: 480 GB SSD | P29: Windows 11 Pro | Q29: MS Office 2007 HB | R29: 1
G30: LIMCNTAI02 | H30: (en blanco) | I30: 10.72.10.139 | J30: Usuario | K30: Dell | L30: 3550P22 | M30: Operativo | N30: 16 GB DDR3 | O30: 480 GB SSD | P30: Windows 11 Pro | Q30: MS Office 2007 HB | R30: 1
C31: Bodegas | D31: CARPIO PONCE GARY ANDRES | E31: Bodeguero | F31: PC | G31: LIMCNTBG01 | H31: LIMH1W10P100 | I31: 10.72.10.81 | J31: Usuario | K31: Dell | L31: 351YN22 | M31: Operativo | N31: 16 GB DDR3 | O31: 480 GB SSD | P31: Windows 11 Pro | Q31: MS Office 2007 HB | R31: 1
C32: Contabilidad | D32: ALVARADO CHAVARRY JIMMY GERARDO | E32: Sub Contralor | F32: PC | G32: LIMCNTSC | H32: (en blanco) | I32: 10.72.10.177 | J32: Usuario | K32: Lenovo | L32: YLT1642S | M32: Operativo | N32: 16 GB DDR5 | O32: 480 GB SSD | P32: Windows 11 Pro | Q32: MS Office 365 HB | R32: 1
D33: CARHUANCOTA CHAVEZ ANDRES ALBERTO | E33: Asistente Senior de Contabilidad | F33: PC | G33: LIMCNTCONT3 | H33: LIMH1W7P101 | I33: 10.72.10.133 | J33: Usuario | K33: Dell | L33: D0HRN22 | M33: Operativo | N33: 16 GB DDR3 | O33: 480 GB SSD | P33: Windows 11 Pro | Q33: MS Office 2007 HB | R33: 1
G34: LIMCNTCONT4 | H34: (en blanco) | I34: (en blanco) | J34: Usuario | K34: HP | L34: MXL5283YYX | M34: Operativo | N34: 16 GB DDR5 | O34: 1000 GB SSD | P34: Windows 11 Pro | Q34: MS Office 365 HB | R34: 1
D35: FLORES RAMIREZ PERCY FERNANDO | E35: Asistente de Cuentas por Cobrar | F35: PC | G35: LIMH1W11AC02 | H35: (en blanco) | I35: 10.72.10.94 | J35: Usuario | K35: Lenovo | L35: (en blanco) | M35: Operativo | N35: 16 GB DDR5 | O35: 1000 GB SSD | P35: Windows 11 Pro | Q35: MS Office 365 HB | R35: 1
D36: HUAYAMA INGAROCA MERCEDES GRACIELA | E36: Practicante de Contabilidad | F36: PC | G36: LIMCNTCONT7 | H36: (en blanco) | I36: 10.72.10.125 | J36: Usuario | K36: Dell | L36: GJWSN22 | M36: Operativo | N36: 16 GB DDR3 | O36: 480 GB SSD | P36: Windows 11 Pro | Q36: MS Office 2007 HB | R36: 1
D37: MILLA GOMEZ ANJALI ABIGAIL | E37: Practicante de Contabilidad | F37: PC | G37: LIMCNTCONT8 | H37: (en blanco) | I37: 10.72.10.129 | J37: Usuario | K37: Dell | L37: CZZFN22 | M37: Operativo | N37: 16 GB DDR3 | O37: 480 GB SSD | P37: Windows 11 Pro | Q37: (en blanco) | R37: 1
D38: ORELLANA CHIPANA MARTIN SANTIAGO | E38: Practicante de Contabilidad | F38: PC | G38: LIMCNTCONT6 | H38: LIMH1W7P57 | I38: 10.72.10.110 | J38: Usuario | K38: Dell | L38: D05FN22 | M38: Operativo | N38: 16 GB DDR3 | O38: 480 GB SSD | P38: Windows 11 Pro | Q38: MS Office 2007 HB | R38: 1
D39: ORELLANA GODOY MELCHORA OLINDA | E39: Contador | F39: PC | G39: (en blanco) | H39: LIMH1W10PC0011 | I39: 10.72.10.73 | J39: Usuario | K39: Dell | L39: 8RLT5X3 | M39: Operativo | N39: 32 GB DDR5 | O39: 500 GB SSD | P39: Windows 11 Pro | Q39: MS Office 2007 HB | R39: 1
D40: SEGOVIA CRISPIN XAVIER ALONSO | E40: Asistente de Contabilidad | F40: PC | G40: (en blanco) | H40: LIMH1W10PC005 | I40: 10.72.10.90 | J40: Usuario | K40: Dell | L40: 7HHT5X3 | M40: Operativo | N40: 32 GB DDR5 | O40: 500 GB SSD | P40: Windows 11 Pro | Q40: MS Office 2007 HB | R40: 1
D41: SISTEMAS DE ACTIVOS FIJOS | E41: Sistema de Activos Fijos | F41: PC | G41: LIMH1GMPC02 | H41: LIMH1GMPC02 | I41: 10.72.10.70 | J41: Usuario | K41: Dell | L41: 353YN22 | M41: Operativo | N41: 8 GB DDR3 | O41: 250 GB SSD | P41: Windows 10 Pro | Q41: MS Office 2007 HB | R41: 1
D42: TISNADO MEGO LEIDER ALFONZO | E42: Encargado de Costos | F42: PC | G42: LIMCNTCONT5 | H42: LIMH1ACPC003 | I42: 10.72.10.53 | J42: Usuario | K42: Dell | L42: D0HFN22 | M42: Operativo | N42: 16 GB DDR3 | O42: 480 GB SSD | P42: Windows 11 Pro | Q42: MS Office 365 HB | R42: 1
...

Sheet PC-Laptop
A3: Propiedad | B3: Unidad | C3: Centro de Costo | D3: Usuario | E3: Cargo | F3: Equipo | G3: Host | H3: Nuevo Nombre Host | I3: IP | J3: Tipo | K3: Marca | L3: S/N | M3: Estado | N3: Ram | O3: Almacenamiento | P3: Sistema Operativo | Q3: Office | R3: Cuenta Equipo
A4: HOTELERA COSTA DEL PACIFICO | B4: Alimentos y Bebidas | C4: Banquetes | D4: FALCON PAZ JULIAN MIGUEL ANGEL | E4: Supervisor Senior de A&B | F4: PC | G4: LIMH1W7P85 | H4: LIMAYBBQ01 | I4: 10.72.10.83 | J4: Usuario | K4: Dell | L4: D04FN22 | M4: Operativo | N4: 16 GB DDR3 | O4: 480 GB SSD | P4: Windows 11 Pro | Q4: MS Office 2007 HB | R4: 1
D5: GOMEZ COBEÑA PERCY BOLIVAR | E5: Capitán de Banquetes | F5: PC | G5: LIMH1W10P061 | H5: LIMAYBBQ02 | I5: 10.72.10.100 | J5: Usuario | K5: Dell | L5: 359ZN22 | M5: Operativo | N5: 16 GB DDR3 | O5: 480 GB SSD | P5: Windows 11 Pro | Q5: MS Office 2007 HB | R5: 1
C6: Gerencia A&B | D6: JARA RISCO GINO | E6: Director de Alimentos y Bebidas | F6: PC | G6: LIMH1W11P071 | H6: (en blanco) | I6: 10.72.10.41 | J6: Usuario | K6: Dell | L6: CZPRN22 | M6: Operativo | N6: 16 GB DDR3 | O6: 480 GB SSD | P6: Windows 11 Pro | Q6: MS Office 2007 HB | R6: 1
D7: MEDINA CASTILLO ALVARO GERARDO | E7: Sub Gerente de A&B | F7: PC | G7: (en blanco) | H7: LIMAYBSGER | I7: 10.72.10.103 | J7: Usuario | K7: Dell | L7: D00RN22 | M7: Operativo | N7: 16 GB DDR3 | O7: 480 GB SSD | P7: Windows 11 Pro | Q7: MS Office 365 HB | R7: 1
D8: RAMOS MAGAN HANNA GRACE | E8: Asistente Administrativa Jr. | F8: PC | G8: (en blanco) | H8: LIMFB02 | I8: 10.72.10.93 | J8: Usuario | K8: Dell | L8: GK6DN22 | M8: Operativo | N8: 16 GB DDR3 | O8: 480 GB SSD | P8: Windows 11 Pro | Q8: MS Office 2007 HB | R8: 1
D9: ROMAN ZUÑIGA ANNIE PAOLA | E9: Gerente de Alimentos y Bebidas | F9: PC | G9: (en blanco) | H9: LIMAYBGER | I9: 10.72.10.161 | J9: Usuario | K9: Dell | L9: 356YN22 | M9: Operativo | N9: 16 GB DDR3 | O9: 480 GB SSD | P9: Windows 11 Pro | Q9: MS Office 365 HB | R9: 1
C10: La Locanda | D10: HERRERA SOLIS CLAUDIA DANIELA FELICITA | E10: Restaurant Manager | F10: PC | G10: limh1w10p011 | H10: LIMAYBLL | I10: 10.72.10.72 | J10: Usuario | K10: Dell | L10: GK2HN22 | M10: Operativo | N10: 16 GB DDR3 | O10: 480 GB SSD | P10: Windows 11 Pro | Q10: MS Office 2007 HB | R10: 1
C11: Le Café | D11: ABANTO CARRANZA ANDREA SOFIA | E11: Consejero Gastronómico | F11: PC | G11: limh1w10p008 | H11: LIMAYBLC02 | I11: 10.72.10.63 | J11: Usuario | K11: Dell | L11: D07QN22 | M11: Operativo | N11: 16 GB DDR3 | O11: 480 GB SSD | P11: Windows 11 Pro | Q11: MS Office 2007 HB | R11: 1
D12: GUTIERREZ OYARDO ANGELA GEORGINA | E12: Consejero Gastronómico | F12: PC | G12: (en blanco) | H12: LIMAYBLC01 | I12: 10.72.10.118 | J12: Usuario | K12: Dell | L12: D1FDN22 | M12: Operativo | N12: 16 GB DDR3 | O12: 480 GB SSD | P12: Windows 11 Pro | Q12: MS Office 365 HB | R12: 1
C13: Lobby | D13: UGAZ OLIVARES PALOMA | E13: Supervisor Senior de A&B | F13: PC | G13: LIMH1W7P95 | H13: LIMAYBLB | I13: 10.72.10.44 | J13: Usuario | K13: Dell | L13: 352YN22 | M13: Operativo | N13: 16 GB DDR3 | O13: 480 GB SSD | P13: Windows 11 Pro | Q13: MS Office 2007 HB | R13: 1
C14: Piso Ejecutivo | D14: RODRIGUEZ ESPINOZA CYANE MILAGROS | E14: Consejero Gastronómico | F14: PC | G14: LIMH1W7P05 | H14: (en blanco) | I14: 10.72.10.164 | J14: Usuario | K14: HP | L14: MXL4321BFX | M14: Operativo | N14: 12 GB DDR3 | O14: 250 GB SSD | P14: Windows 11 Pro | Q14: MS Office 2007 HB | R14: 1
C15: Room Service | D15: HUAPAYA PEREZ LUIS ANGEL | E15: Supervisor de A&B | F15: PC | G15: limh1w10p005 | H15: LIMAYBRS | I15: 10.72.10.87 | J15: Usuario | K15: Dell | L15: GJVQN22 | M15: Operativo | N15: 16 GB DDR3 | O15: 480 GB SSD | P15: Windows 11 Pro | Q15: MS Office 2007 HB | R15: 1
C16: Steward | D16: VEGA ARRATEA JAVIER VICTOR | E16: Supervisor Jr. de Steward | F16: PC | G16: (en blanco) | H16: LIMFBSW | I16: 10.72.10.84 | J16: Usuario | K16: Dell | L16: GK2QN22 | M16: Operativo | N16: 16 GB DDR3 | O16: 480 GB SSD | P16: Windows 11 Pro | Q16: MS Office 2007 HB | R16: 1
B17: Total Alimentos y Bebidas | R17: 13
B18: Cocina | C18: Calidad | D18: ALEGRE ANGELES FERNANDA LUCIA | E18: Jefa de Aseguramiento de Calidad | F18: PC | G18: (en blanco) | H18: LIMCOC06 | I18: (en blanco) | J18: Usuario | K18: HP | L18: 9CG6262196 | M18: Operativo | N18: 8 GB DDR4 | O18: 250 GB SSD | P18: Windows 11 Pro | Q18: MS Office 365 HB | R18: 1
D19: CONDORI MORENO ELIZABETH CINTHIA | E19: Asistente de Calidad | F19: PC | G19: (en blanco) | H19: LIMCOC05 | I19: 10.72.10.138 | J19: Usuario | K19: Dell | L19: D01GN22 | M19: Operativo | N19: 16 GB DDR3 | O19: 480 GB SSD | P19: Windows 11 Pro | Q19: MS Office 365 HB | R19: 1
C20: Cocina | D20: LOPEZ PEREZ JUAN | E20: Chef Ejecutivo | F20: PC | G20: LIMH1W10FB010 | H20: LIMCHEF | I20: 10.72.10.106 | J20: Usuario | K20: Dell | L20: D09HN22 | M20: Operativo | N20: 16 GB DDR3 | O20: 480 GB SSD | P20: Windows 11 Pro | Q20: MS Office 365 HB | R20: 1
D21: TRONCOS REQUEJO MELANIE ALICIA | E21: Practicante Administrativo de Cocina | F21: PC | G21: (en blanco) | H21: LIMCOC02 | I21: 10.72.10.49 | J21: Usuario | K21: Dell | L21: D1HFN22 | M21: Operativo | N21: 16 GB DDR3 | O21: 480 GB SSD | P21: Windows 11 Pro | Q21: MS Office 365 HB | R21: 1
C22: Cocina La Locanda | D22: BAUTISTA CARDENAS MIGUEL ALEJANDRO | E22: Sub Chef | F22: PC | G22: LIMH1FBPC06 | H22: LIMCOC04 | I22: 10.72.10.157 | J22: Usuario | K22: Dell | L22: CZYQN22 | M22: Operativo | N22: 16 GB DDR3 | O22: 480 GB SSD | P22: Windows 11 Pro | Q22: MS Office 2007 HB | R22: 1
G23: LIMH1W11FB12 | H23: LIMCOC03 | I23: 10.72.10.144 | J23: Usuario | K23: Dell | L23: CZNQN22 | M23: Operativo | N23: 16 GB DDR3 | O23: 250 GB SSD | P23: Windows 11 Pro | Q23: MS Office 2007 HB | R23: 1
C24: Pastelería | D24: CHAVEZ LING SUSANA BETSABE | E24: Supervisor Pasteleria / Panadería | F24: PC | G24: LIMH1W11FB12 | H24: LIMCOC01 | I24: 10.72.10.99 | J24: Usuario | K24: Dell | L24: 3510P22 | M24: Operativo | N24: 12 GB DDR3 | O24: 480 GB SSD | P24: Windows 11 Pro | Q24: MS Office 365 HB | R24: 1
B25: Total Cocina | R25: 7
B26: Compras | C26: Compras | D26: CASTRO MORA NELLY YOLANDA | E26: Gerente de Compras Regional | F26: Laptop | G26: (en blanco) | H26: LIMPU01 | I26: 10.72.10.101 | J26: Usuario | K26: Lenovo | L26: PF3KWH96 | M26: Operativo | N26: 16 GB DDR4 | O26: 1000 GB SSD | P26: Windows 11 Pro | Q26: MS Office 365 HB | R26: 1
D27: OBARA AVI JUAN FERNANDO | E27: Gerente de Compras | F27: PC | G27: LIMH1PUPC001 | H27: LIMCOMPGC | I27: 10.72.10.51 | J27: Usuario | K27: Dell | L27: 35CXN22 | M27: Operativo | N27: 16 GB DDR3 | O27: 480 GB SSD | P27: Windows 11 Pro | Q27: MS Office 2007 HB | R27: 1
B28: Total Compras | R28: 2
B29: Contraloría | C29: Auditoría de Ingresos | D29: MOTA CASTRO JIM EDUARDO | E29: Auditor de Ingresos | F29: PC | G29: LIMH1W7P65 | H29: LIMCNTAI | I29: 10.72.10.138 | J29: Usuario | K29: Dell | L29: D09RN22 | M29: Operativo | N29: 16 GB DDR3 | O29: 480 GB SSD | P29: Windows 11 Pro | Q29: MS Office 2007 HB | R29: 1
G30: (en blanco) | H30: LIMCNTAI02 | I30: 10.72.10.139 | J30: Usuario | K30: Dell | L30: 3550P22 | M30: Operativo | N30: 16 GB DDR3 | O30: 480 GB SSD | P30: Windows 11 Pro | Q30: MS Office 2007 HB | R30: 1
C31: Bodegas | D31: CARPIO PONCE GARY ANDRES | E31: Bodeguero | F31: PC | G31: LIMH1W10P100 | H31: LIMCNTBG01 | I31: 10.72.10.81 | J31: Usuario | K31: Dell | L31: 351YN22 | M31: Operativo | N31: 16 GB DDR3 | O31: 480 GB SSD | P31: Windows 11 Pro | Q31: MS Office 2007 HB | R31: 1
C32: Contabilidad | D32: CARHUANCOTA CHAVEZ ANDRES ALBERTO | E32: Asistente Senior de Contabilidad | F32: PC | G32: LIMH1W7P101 | H32: LIMCNTCONT3 | I32: 10.72.10.133 | J32: Usuario | K32: Dell | L32: D0HRN22 | M32: Operativo | N32: 16 GB DDR3 | O32: 480 GB SSD | P32: Windows 11 Pro | Q32: MS Office 2007 HB | R32: 1
G33: (en blanco) | H33: LIMCNTCONT4 | I33: (en blanco) | J33: Usuario | K33: HP | L33: MXL5283YYX | M33: Operativo | N33: 16 GB DDR5 | O33: 1000 GB SSD | P33: Windows 11 Pro | Q33: MS Office 365 HB | R33: 1
D34: FLORES RAMIREZ PERCY FERNANDO | E34: Asistente de Cuentas por Cobrar | F34: PC | G34: (en blanco) | H34: LIMH1W11AC02 | I34: 10.72.10.94 | J34: Usuario | K34: Lenovo | L34: (en blanco) | M34: Operativo | N34: 16 GB DDR5 | O34: 1000 GB SSD | P34: Windows 11 Pro | Q34: MS Office 365 HB | R34: 1
D35: HUAYAMA INGAROCA MERCEDES GRACIELA | E35: Practicante de Contabilidad | F35: PC | G35: (en blanco) | H35: LIMCNTCONT7 | I35: 10.72.10.125 | J35: Usuario | K35: Dell | L35: GJWSN22 | M35: Operativo | N35: 16 GB DDR3 | O35: 480 GB SSD | P35: Windows 11 Pro | Q35: MS Office 2007 HB | R35: 1
D36: MILLA GOMEZ ANJALI ABIGAIL | E36: Practicante de Contabilidad | F36: PC | G36: (en blanco) | H36: LIMCNTCONT8 | I36: 10.72.10.129 | J36: Usuario | K36: Dell | L36: CZZFN22 | M36: Operativo | N36: 16 GB DDR3 | O36: 480 GB SSD | P36: Windows 11 Pro | Q36: (en blanco) | R36: 1
D37: ORELLANA CHIPANA MARTIN SANTIAGO | E37: Practicante de Contabilidad | F37: PC | G37: LIMH1W7P57 | H37: LIMCNTCONT6 | I37: 10.72.10.110 | J37: Usuario | K37: Dell | L37: D05FN22 | M37: Operativo | N37: 16 GB DDR3 | O37: 480 GB SSD | P37: Windows 11 Pro | Q37: MS Office 2007 HB | R37: 1
D38: ORELLANA GODOY MELCHORA OLINDA | E38: Contador | F38: PC | G38: LIMH1W10PC0011 | H38: (en blanco) | I38: 10.72.10.73 | J38: Usuario | K38: Dell | L38: 8RLT5X3 | M38: Operativo | N38: 32 GB DDR5 | O38: 500 GB SSD | P38: Windows 11 Pro | Q38: MS Office 2007 HB | R38: 1
D39: SEGOVIA CRISPIN XAVIER ALONSO | E39: Asistente de Contabilidad | F39: PC | G39: LIMH1W10PC005 | H39: (en blanco) | I39: 10.72.10.90 | J39: Usuario | K39: Dell | L39: 7HHT5X3 | M39: Operativo | N39: 32 GB DDR5 | O39: 500 GB SSD | P39: Windows 11 Pro | Q39: MS Office 2007 HB | R39: 1
D40: SISTEMAS DE ACTIVOS FIJOS | E40: Sistema de Activos Fijos | F40: PC | G40: LIMH1GMPC02 | H40: LIMH1GMPC02 | I40: 10.72.10.70 | J40: Usuario | K40: Dell | L40: 353YN22 | M40: Operativo | N40: 8 GB DDR3 | O40: 250 GB SSD | P40: Windows 10 Pro | Q40: MS Office 2007 HB | R40: 1
D41: ALVARADO CHAVARRY JIMMY GERARDO | E41: Sub Contralor | F41: PC | G41: (en blanco) | H41: LIMCNTSC | I41: 10.72.10.177 | J41: Usuario | K41: Lenovo | L41: YLT1642S | M41: Operativo | N41: 16 GB DDR5 | O41: 480 GB SSD | P41: Windows 11 Pro | Q41: MS Office 365 HB | R41: 1
D42: TISNADO MEGO LEIDER ALFONZO | E42: Encargado de Costos | F42: PC | G42: LIMH1ACPC003 | H42: LIMCNTCONT5 | I42: 10.72.10.53 | J42: Usuario | K42: Dell | L42: D0HFN22 | M42: Operativo | N42: 16 GB DDR3 | O42: 480 GB SSD | P42: Windows 11 Pro | Q42: MS Office 365 HB | R42: 1
...

Sheet ImpresoasDinamica
A3: Propiedad | B3: Equipo | C3: Marca | D3: Modelo | E3: S/N | F3: IP | G3: Observación | H3: Cantidad Impresoras
A4: Prov. DATACONT | B4: Impresora | C4: Canon | D4: iR1730i | E4: QFX06245 | F4: 10.72.8.215 | G4: 2do Piso - Oficina Auditor de Ingresos | H4: 1
D5: iR1643i II | E5: 35E33608 | F5: 10.72.8.211 | G5: 1er Piso - Front Desk - Recepción | H5: 1
E6: 35E33607 | F6: 10.72.8.153 | G6: 1er Piso - Front Desk - Recepción | H6: 1
C7: Epson | D7: WF-C5790 Series | E7: X3B7002433 | F7: 10.72.8.191 | G7: 2do Piso - Oficina Banquetes | H7: 1
E8: X3B7003659 | F8: 10.72.8.197 | G8: 3er Piso - Reservas | H8: 1
E9: X3B7003660 | F9: 10.72.8.204 | G9: 1er Piso - Room Service | H9: 1
E10: X3B7003661 | F10: 10.72.8.132 | G10: 1er Sotano - Steward - Limpieza | H10: 1
E11: X3B7003671 | F11: 10.72.8.208 | G11: 1er Piso - Caja Lobby Bar | H11: 1
E12: X3B7003703 | F12: 10.9.10.153 | G12: 1er Piso Gym | H12: 1
E13: X3B7003711 | F13: 10.72.8.205 | G13: 1er Piso - Recepción - Back Office | H13: 1
E14: X3B7003739 | F14: 10.72.10.43 | G14: 1er Piso Compras | H14: 1
E15: X3B7003876 | F15: 10.72.8.220 | G15: 1er Piso - Oficina AyB | H15: 1
D16: WF-C5890 Series | E16: XBJZ017266 | F16: 10.72.8.229 | G16: 1er Sotano - Housekeeping | H16: 1
E17: XBJZ017602 | F17: 10.72.8.206 | G17: 1er Piso - Bodega | H17: 1
E18: XBJZ017603 | F18: 10.72.8.196 | G18: 1er Piso - Conserge | H18: 1
E19: XBJZ021745 | F19: 10.72.8.219 | G19: 1er Piso - Oficina Chef | H19: 1
E20: XBJZ021772 | F20: 10.72.8.151 | G20: 3er Piso - Gerencia General | H20: 1
E21: XBJZ027512 | F21: 10.72.8.210 | G21: 3er Piso - Ventas | H21: 1
C22: Sharp | D22: MX-3070V | E22: 3500930400 | F22: 10.72.8.200 | G22: 1er Sotano - RRHH - Sistemas | H22: 1
D23: MX-M3070 | E23: 9502370Y00 | F23: 10.72.8.207 | G23: 3er Piso - Contabilidad | H23: 1
E24: 15064216 | F24: 10.72.8.203 | G24: 2do Piso - Seguridad | H24: 1
A25: Total general | H25: 21

Sheet Micros
A3: Propiedad | B3: Unidad | C3: Centro de Costo | D3: Cargo | E3: Usuario | F3: Equipo | G3: Marca | H3: Modelo | I3: S/N | J3: IP | K3: Estado | L3: Cuenta de Equipo
A4: HOTELERA COSTA DEL PACIFICO | B4: Alimentos y Bebidas | C4: Banquetes | D4: Banquetes | E4: Banquetes | F4: Micros | G4: Oracle | H4: Workstation 8 | I4: 5365ECB05002311 | J4: 10.72.8.246 | K4: Operativo | L4: 1
C5: La Fondue | D5: Caja La Fondue | E5: Caja La Fondue | F5: Micros | G5: Oracle | H5: Workstation 8 | I5: 5365ECB05002309 | J5: 10.72.8.247 | K5: Operativo | L5: 1
C6: Room Service | D6: Caja Room Service | E6: Caja Room Service | F6: Micros | G6: Oracle | H6: Workstation 8 | I6: 5365ECB05002312 | J6: 10.72.8.238 | K6: Operativo | L6: 1
C7: Le Café | D7: Caja Le Café | E7: Caja Le Café | F7: Micros | G7: Oracle | H7: Workstation 8 | I7: 5365ECB05002324 | J7: 10.72.8.245 | K7: Operativo | L7: 1
C8: Lobby Bar | D8: Caja Lobby Bar | E8: Caja Lobby Bar | F8: Micros | G8: Oracle | H8: Workstation 8 | I8: 5365ECB05002273 | J8: 10.72.8.237 | K8: Operativo | L8: 1
C9: La Locanda | D9: Caja La Locanda | E9: Caja La Locanda | F9: Micros | G9: Oracle | H9: Workstation 8 | I9: 5365ECB05002282 | J9: 10.72.8.236 | K9: Operativo | L9: 1
B10: Tecnologias de Información | C10: Tecnologias de Información | D10: Tecnologias de Información | E10: Tecnologias de Información | F10: Micros | G10: Oracle | H10: Workstation 8 | I10: 5365ECB05002274 | J10: (en blanco) | K10: Custodia - Operativo | L10: 1
I11: 5365ECB05002291 | J11: (en blanco) | K11: Custodia - Operativo | L11: 1
A12: Total general | L12: 8

Sheet Datos
B4: Equipo | C4: Tipo | D4: Marca | E4: Modelo | F4: S/N | G4: P/N | H4: Operador | I4: Linea | J4: IMEI1 | K4: IMEI2 | L4: Mac Address | M4: Nombre Host | N4: Nuevo Nombre Host | O4: Procesador | P4: Generación Procesador | Q4: Chip Video | R4: Ram | S4: Ram Actual | T4: Almacenamiento | U4: Pantalla | V4: IP | W4: Sistema Operativo | X4: Antivirus | Y4: Office | Z4: Cuenta Gmail | AA4: Clave Gmail | AB4: Fech. Ini Garantía | AC4: Fech. Fin Garantía | AD4: Propiedad | AE4: Estado | AF4: DNI | AG4: Código | AH4: Usuario | AI4: Cargo | AJ4: Centro Costo | AK4: Unidad
B5: PC | C5: Usuario | D5: Dell | H5: Movistar | O5: Intel Core i3 | P5: 1era Gen. | Q5: Intel Integrado | R5: 4 GB DDR3 | T5: 250 GB HHD | U5: 14" | W5: Windows 11 Pro | X5: Si | Y5: MS Office 2007 HB | AD5: HOTELERA COSTA DEL PACIFICO | AE5: Operativo
B6: Laptop | C6: Servidor | D6: Lenovo | H6: Claro | O6: Intel Core i5 | P6: 2da Gen. | Q6: NVIDEA | R6: 8 GB DDR3 | T6: 500 GB HDD | U6: 15" | W6: Windows 11 IoT Enterprise LTSC | X6: No | Y6: MS Office 365 HB | AD6: Prov. DATACONT | AE6: Inoperativo
B7: Monitor | D7: HP | H7: Entel | O7: Intel Core i7 | P7: 3era Gen. | Q7: AMD ATI | R7: 12 GB DDR3 | T7: 1000 GB HDD | U7: 17" | W7: Windows 10 Pro | X7: Pendiente | AE7: Por Revisar
B8: Celular | D8: Toshiba | O8: Intel Core i9 | P8: 4ta Gen. | R8: 16 GB DDR3 | T8: 250 GB SSD | U8: 19" | W8: Windows Server 2008 | X8: N/A | AE8: Por Reparar
B9: Impresora | D9: Samsung | O9: Intel Xeon | P9: 5ta Gen. | R9: 20 GB DDR3 | T9: 480 GB SSD | U9: 20" | W9: Windows Server 2012 | AE9: Por Repotenciar
B10: Servidor | D10: LG | O10: AMD Ryzen | P10: 6ta Gen. | R10: 32 GB DDR3 | T10: 500 GB SSD | U10: 22" | W10: Windows Server 2022 | AE10: Obsoleto
B11: Access Point | D11: ZTE | O11: Movil | P11: 7ma Gen. | R11: 8 GB DDR4 | T11: 1000 GB SSD | U11: 24" | W11: Windows Server 2025 | AE11: Custodia - Operativo
B12: Switch | D12: Apple | O12: Intel Atom | P12: 8va Gen. | R12: 12 GB DDR4 | T12: 16 GB | U12: 27" | W12: Android | AE12: Custodia - Inoperativo
B13: Router | D13: Xiaomi | O13: ARM | P13: 9va Gen. | R13: 16 GB DDR4 | T13: 32gb | U13: 32" | W13: iOS | AE13: Custodia - Por Revisar
B14: Anexos IP | D14: Oppo | O14: Intel Celeron | P14: 10ma Gen. | R14: 20 GB DDR4 | T14: 64 GB | U14: 42" | W14: Windows 7 Pro | AE14: Custodia - Por Reparar
B15: Anexo Analógico | D15: Gigabyte | P15: 11va Gen. | R15: 32 GB DDR4 | T15: 128 GB | U15: 49" | W15: Windows 10 Enterprise | AE15: Custodia - Por Repotenciar
B16: TV | D16: Epson | P16: 12va Gen. | R16: 64 GB DDR4 | T16: 250 GB | U16: 4.7" | W16: Linux | AE16: Custodia - Obsoleto
B17: Parlantes | D17: Canon | P17: 13va Gen. | R17: 128 GB DDR4 | T17: 480 GB SSD + 500 GB HDD | U17: 6.1" | W17: Windows Server 2016
B18: Tablet | D18: Oracle | P18: 14va Gen. | R18: 8 GB DDR5 | T18: 500 GB SSD + 500 GB HDD | U18: 6.6"
B19: Micros | D19: Sharp | P19: Ultra | R19: 12 GB DDR5 | T19: 16 TB RAID | U19: 6.75"
D20: Qnap | R20: 16 GB DDR5 | T20: 6 TB RAID | U20: 6.8"
D21: Honor | R21: 20 GB DDR5 | T21: 1 TB | U21: 8"
D22: Synology | R22: 32 GB DDR5 | T22: 2 TB | U22: 9"
R23: 64 GB DDR5 | T23: 4 TB | U23: 10"
R24: 128 GB DDR5 | U24: 11"
R25: 4GB + 8GB | U25: 12"
R26: 3GB | U26: 8.9"
R27: 2GB
R28: 4GB
R29: 6GB
